2022-06-16 13:34:41 ERROR 409 response executing GraphQL.
2022-06-16 13:34:41 ERROR {"errors":[{"message":"Error 1062: Duplicate entry 'auto_song_labeller-322855' for key 'ix_projects_name_entity_id'","path":["upsertSweep"]}],"data":{"upsertSweep":null}}
2022-06-16 13:34:41 ERROR Traceback (most recent call last):
  File "/Users/petr/Documents/fun_stuff/auto_song_labeller/nerAL/lib/python3.8/site-packages/wandb/sdk/lib/retry.py", line 102, in __call__
    result = self._call_fn(*args, **kwargs)
  File "/Users/petr/Documents/fun_stuff/auto_song_labeller/nerAL/lib/python3.8/site-packages/wandb/sdk/internal/internal_api.py", line 140, in execute
    return self.client.execute(*args, **kwargs)
  File "/Users/petr/Documents/fun_stuff/auto_song_labeller/nerAL/lib/python3.8/site-packages/wandb/vendor/gql-0.2.0/wandb_gql/client.py", line 52, in execute
    result = self._get_result(document, *args, **kwargs)
  File "/Users/petr/Documents/fun_stuff/auto_song_labeller/nerAL/lib/python3.8/site-packages/wandb/vendor/gql-0.2.0/wandb_gql/client.py", line 60, in _get_result
    return self.transport.execute(document, *args, **kwargs)
  File "/Users/petr/Documents/fun_stuff/auto_song_labeller/nerAL/lib/python3.8/site-packages/wandb/vendor/gql-0.2.0/wandb_gql/transport/requests.py", line 39, in execute
    request.raise_for_status()
  File "/Users/petr/Documents/fun_stuff/auto_song_labeller/nerAL/lib/python3.8/site-packages/requests/models.py", line 1022, in raise_for_status
    raise HTTPError(http_error_msg, response=self)
requests.exceptions.HTTPError: 409 Client Error: Conflict for url: https://api.wandb.ai/graphql

During handling of the above exception, another exception occurred:

Traceback (most recent call last):
  File "/Users/petr/Documents/fun_stuff/auto_song_labeller/nerAL/lib/python3.8/site-packages/wandb/apis/normalize.py", line 22, in wrapper
    return func(*args, **kwargs)
  File "/Users/petr/Documents/fun_stuff/auto_song_labeller/nerAL/lib/python3.8/site-packages/wandb/sdk/internal/internal_api.py", line 1915, in upsert_sweep
    raise (e)
  File "/Users/petr/Documents/fun_stuff/auto_song_labeller/nerAL/lib/python3.8/site-packages/wandb/sdk/internal/internal_api.py", line 1901, in upsert_sweep
    response = self.gql(
  File "/Users/petr/Documents/fun_stuff/auto_song_labeller/nerAL/lib/python3.8/site-packages/wandb/sdk/lib/retry.py", line 118, in __call__
    if not check_retry_fn(e):
  File "/Users/petr/Documents/fun_stuff/auto_song_labeller/nerAL/lib/python3.8/site-packages/wandb/sdk/internal/internal_api.py", line 1892, in no_retry_4xx
    raise UsageError(body["errors"][0]["message"])
wandb.errors.UsageError: Error 1062: Duplicate entry 'auto_song_labeller-322855' for key 'ix_projects_name_entity_id'

During handling of the above exception, another exception occurred:

Traceback (most recent call last):
  File "/Users/petr/Documents/fun_stuff/auto_song_labeller/nerAL/lib/python3.8/site-packages/wandb/cli/cli.py", line 96, in wrapper
    return func(*args, **kwargs)
  File "/Users/petr/Documents/fun_stuff/auto_song_labeller/nerAL/lib/python3.8/site-packages/wandb/cli/cli.py", line 859, in sweep
    sweep_id, warnings = api.upsert_sweep(
  File "/Users/petr/Documents/fun_stuff/auto_song_labeller/nerAL/lib/python3.8/site-packages/wandb/apis/internal.py", line 102, in upsert_sweep
    return self.api.upsert_sweep(*args, **kwargs)
  File "/Users/petr/Documents/fun_stuff/auto_song_labeller/nerAL/lib/python3.8/site-packages/wandb/apis/normalize.py", line 58, in wrapper
    raise CommError(message, err).with_traceback(sys.exc_info()[2])
  File "/Users/petr/Documents/fun_stuff/auto_song_labeller/nerAL/lib/python3.8/site-packages/wandb/apis/normalize.py", line 22, in wrapper
    return func(*args, **kwargs)
  File "/Users/petr/Documents/fun_stuff/auto_song_labeller/nerAL/lib/python3.8/site-packages/wandb/sdk/internal/internal_api.py", line 1915, in upsert_sweep
    raise (e)
  File "/Users/petr/Documents/fun_stuff/auto_song_labeller/nerAL/lib/python3.8/site-packages/wandb/sdk/internal/internal_api.py", line 1901, in upsert_sweep
    response = self.gql(
  File "/Users/petr/Documents/fun_stuff/auto_song_labeller/nerAL/lib/python3.8/site-packages/wandb/sdk/lib/retry.py", line 118, in __call__
    if not check_retry_fn(e):
  File "/Users/petr/Documents/fun_stuff/auto_song_labeller/nerAL/lib/python3.8/site-packages/wandb/sdk/internal/internal_api.py", line 1892, in no_retry_4xx
    raise UsageError(body["errors"][0]["message"])
wandb.errors.CommError: Error 1062: Duplicate entry 'auto_song_labeller-322855' for key 'ix_projects_name_entity_id'

2022-06-16 13:36:08 ERROR 400 response executing GraphQL.
2022-06-16 13:36:08 ERROR {"errors":[{"message":"name required for project query","path":["project"]}],"data":{"project":null}}
2022-06-16 13:36:08 ERROR Traceback (most recent call last):
  File "/Users/petr/Documents/fun_stuff/auto_song_labeller/nerAL/lib/python3.8/site-packages/wandb/apis/normalize.py", line 22, in wrapper
    return func(*args, **kwargs)
  File "/Users/petr/Documents/fun_stuff/auto_song_labeller/nerAL/lib/python3.8/site-packages/wandb/sdk/internal/internal_api.py", line 571, in sweep
    response = self.gql(
  File "/Users/petr/Documents/fun_stuff/auto_song_labeller/nerAL/lib/python3.8/site-packages/wandb/sdk/lib/retry.py", line 102, in __call__
    result = self._call_fn(*args, **kwargs)
  File "/Users/petr/Documents/fun_stuff/auto_song_labeller/nerAL/lib/python3.8/site-packages/wandb/sdk/internal/internal_api.py", line 140, in execute
    return self.client.execute(*args, **kwargs)
  File "/Users/petr/Documents/fun_stuff/auto_song_labeller/nerAL/lib/python3.8/site-packages/wandb/vendor/gql-0.2.0/wandb_gql/client.py", line 52, in execute
    result = self._get_result(document, *args, **kwargs)
  File "/Users/petr/Documents/fun_stuff/auto_song_labeller/nerAL/lib/python3.8/site-packages/wandb/vendor/gql-0.2.0/wandb_gql/client.py", line 60, in _get_result
    return self.transport.execute(document, *args, **kwargs)
  File "/Users/petr/Documents/fun_stuff/auto_song_labeller/nerAL/lib/python3.8/site-packages/wandb/vendor/gql-0.2.0/wandb_gql/transport/requests.py", line 39, in execute
    request.raise_for_status()
  File "/Users/petr/Documents/fun_stuff/auto_song_labeller/nerAL/lib/python3.8/site-packages/requests/models.py", line 1022, in raise_for_status
    raise HTTPError(http_error_msg, response=self)
requests.exceptions.HTTPError: 400 Client Error: Bad Request for url: https://api.wandb.ai/graphql

During handling of the above exception, another exception occurred:

Traceback (most recent call last):
  File "/Users/petr/Documents/fun_stuff/auto_song_labeller/nerAL/lib/python3.8/site-packages/wandb/cli/cli.py", line 96, in wrapper
    return func(*args, **kwargs)
  File "/Users/petr/Documents/fun_stuff/auto_song_labeller/nerAL/lib/python3.8/site-packages/wandb/cli/cli.py", line 1210, in agent
    wandb_agent.agent(sweep_id, entity=entity, project=project, count=count)
  File "/Users/petr/Documents/fun_stuff/auto_song_labeller/nerAL/lib/python3.8/site-packages/wandb/wandb_agent.py", line 606, in agent
    return run_agent(
  File "/Users/petr/Documents/fun_stuff/auto_song_labeller/nerAL/lib/python3.8/site-packages/wandb/wandb_agent.py", line 548, in run_agent
    agent.run()
  File "/Users/petr/Documents/fun_stuff/auto_song_labeller/nerAL/lib/python3.8/site-packages/wandb/wandb_agent.py", line 181, in run
    sweep_obj = self._api.sweep(self._sweep_id, "{}")
  File "/Users/petr/Documents/fun_stuff/auto_song_labeller/nerAL/lib/python3.8/site-packages/wandb/apis/internal.py", line 99, in sweep
    return self.api.sweep(*args, **kwargs)
  File "/Users/petr/Documents/fun_stuff/auto_song_labeller/nerAL/lib/python3.8/site-packages/wandb/apis/normalize.py", line 24, in wrapper
    raise CommError(err.response, err)
wandb.errors.CommError: <Response [400]>

2022-06-16 13:36:45 ERROR 400 response executing GraphQL.
2022-06-16 13:36:45 ERROR {"errors":[{"message":"name required for project query","path":["project"]}],"data":{"project":null}}
2022-06-16 13:36:45 ERROR Traceback (most recent call last):
  File "/Users/petr/Documents/fun_stuff/auto_song_labeller/nerAL/lib/python3.8/site-packages/wandb/apis/normalize.py", line 22, in wrapper
    return func(*args, **kwargs)
  File "/Users/petr/Documents/fun_stuff/auto_song_labeller/nerAL/lib/python3.8/site-packages/wandb/sdk/internal/internal_api.py", line 571, in sweep
    response = self.gql(
  File "/Users/petr/Documents/fun_stuff/auto_song_labeller/nerAL/lib/python3.8/site-packages/wandb/sdk/lib/retry.py", line 102, in __call__
    result = self._call_fn(*args, **kwargs)
  File "/Users/petr/Documents/fun_stuff/auto_song_labeller/nerAL/lib/python3.8/site-packages/wandb/sdk/internal/internal_api.py", line 140, in execute
    return self.client.execute(*args, **kwargs)
  File "/Users/petr/Documents/fun_stuff/auto_song_labeller/nerAL/lib/python3.8/site-packages/wandb/vendor/gql-0.2.0/wandb_gql/client.py", line 52, in execute
    result = self._get_result(document, *args, **kwargs)
  File "/Users/petr/Documents/fun_stuff/auto_song_labeller/nerAL/lib/python3.8/site-packages/wandb/vendor/gql-0.2.0/wandb_gql/client.py", line 60, in _get_result
    return self.transport.execute(document, *args, **kwargs)
  File "/Users/petr/Documents/fun_stuff/auto_song_labeller/nerAL/lib/python3.8/site-packages/wandb/vendor/gql-0.2.0/wandb_gql/transport/requests.py", line 39, in execute
    request.raise_for_status()
  File "/Users/petr/Documents/fun_stuff/auto_song_labeller/nerAL/lib/python3.8/site-packages/requests/models.py", line 1022, in raise_for_status
    raise HTTPError(http_error_msg, response=self)
requests.exceptions.HTTPError: 400 Client Error: Bad Request for url: https://api.wandb.ai/graphql

During handling of the above exception, another exception occurred:

Traceback (most recent call last):
  File "/Users/petr/Documents/fun_stuff/auto_song_labeller/nerAL/lib/python3.8/site-packages/wandb/cli/cli.py", line 96, in wrapper
    return func(*args, **kwargs)
  File "/Users/petr/Documents/fun_stuff/auto_song_labeller/nerAL/lib/python3.8/site-packages/wandb/cli/cli.py", line 1210, in agent
    wandb_agent.agent(sweep_id, entity=entity, project=project, count=count)
  File "/Users/petr/Documents/fun_stuff/auto_song_labeller/nerAL/lib/python3.8/site-packages/wandb/wandb_agent.py", line 606, in agent
    return run_agent(
  File "/Users/petr/Documents/fun_stuff/auto_song_labeller/nerAL/lib/python3.8/site-packages/wandb/wandb_agent.py", line 548, in run_agent
    agent.run()
  File "/Users/petr/Documents/fun_stuff/auto_song_labeller/nerAL/lib/python3.8/site-packages/wandb/wandb_agent.py", line 181, in run
    sweep_obj = self._api.sweep(self._sweep_id, "{}")
  File "/Users/petr/Documents/fun_stuff/auto_song_labeller/nerAL/lib/python3.8/site-packages/wandb/apis/internal.py", line 99, in sweep
    return self.api.sweep(*args, **kwargs)
  File "/Users/petr/Documents/fun_stuff/auto_song_labeller/nerAL/lib/python3.8/site-packages/wandb/apis/normalize.py", line 24, in wrapper
    raise CommError(err.response, err)
wandb.errors.CommError: <Response [400]>

2022-06-16 13:54:13 ERROR 400 response executing GraphQL.
2022-06-16 13:54:13 ERROR {"errors":[{"message":"name required for project query","path":["project"]}],"data":{"project":null}}
2022-06-16 13:54:13 ERROR Traceback (most recent call last):
  File "/Users/petr/Documents/fun_stuff/auto_song_labeller/nerAL/lib/python3.8/site-packages/wandb/apis/normalize.py", line 22, in wrapper
    return func(*args, **kwargs)
  File "/Users/petr/Documents/fun_stuff/auto_song_labeller/nerAL/lib/python3.8/site-packages/wandb/sdk/internal/internal_api.py", line 571, in sweep
    response = self.gql(
  File "/Users/petr/Documents/fun_stuff/auto_song_labeller/nerAL/lib/python3.8/site-packages/wandb/sdk/lib/retry.py", line 102, in __call__
    result = self._call_fn(*args, **kwargs)
  File "/Users/petr/Documents/fun_stuff/auto_song_labeller/nerAL/lib/python3.8/site-packages/wandb/sdk/internal/internal_api.py", line 140, in execute
    return self.client.execute(*args, **kwargs)
  File "/Users/petr/Documents/fun_stuff/auto_song_labeller/nerAL/lib/python3.8/site-packages/wandb/vendor/gql-0.2.0/wandb_gql/client.py", line 52, in execute
    result = self._get_result(document, *args, **kwargs)
  File "/Users/petr/Documents/fun_stuff/auto_song_labeller/nerAL/lib/python3.8/site-packages/wandb/vendor/gql-0.2.0/wandb_gql/client.py", line 60, in _get_result
    return self.transport.execute(document, *args, **kwargs)
  File "/Users/petr/Documents/fun_stuff/auto_song_labeller/nerAL/lib/python3.8/site-packages/wandb/vendor/gql-0.2.0/wandb_gql/transport/requests.py", line 39, in execute
    request.raise_for_status()
  File "/Users/petr/Documents/fun_stuff/auto_song_labeller/nerAL/lib/python3.8/site-packages/requests/models.py", line 1022, in raise_for_status
    raise HTTPError(http_error_msg, response=self)
requests.exceptions.HTTPError: 400 Client Error: Bad Request for url: https://api.wandb.ai/graphql

During handling of the above exception, another exception occurred:

Traceback (most recent call last):
  File "/Users/petr/Documents/fun_stuff/auto_song_labeller/nerAL/lib/python3.8/site-packages/wandb/cli/cli.py", line 96, in wrapper
    return func(*args, **kwargs)
  File "/Users/petr/Documents/fun_stuff/auto_song_labeller/nerAL/lib/python3.8/site-packages/wandb/cli/cli.py", line 1210, in agent
    wandb_agent.agent(sweep_id, entity=entity, project=project, count=count)
  File "/Users/petr/Documents/fun_stuff/auto_song_labeller/nerAL/lib/python3.8/site-packages/wandb/wandb_agent.py", line 606, in agent
    return run_agent(
  File "/Users/petr/Documents/fun_stuff/auto_song_labeller/nerAL/lib/python3.8/site-packages/wandb/wandb_agent.py", line 548, in run_agent
    agent.run()
  File "/Users/petr/Documents/fun_stuff/auto_song_labeller/nerAL/lib/python3.8/site-packages/wandb/wandb_agent.py", line 181, in run
    sweep_obj = self._api.sweep(self._sweep_id, "{}")
  File "/Users/petr/Documents/fun_stuff/auto_song_labeller/nerAL/lib/python3.8/site-packages/wandb/apis/internal.py", line 99, in sweep
    return self.api.sweep(*args, **kwargs)
  File "/Users/petr/Documents/fun_stuff/auto_song_labeller/nerAL/lib/python3.8/site-packages/wandb/apis/normalize.py", line 24, in wrapper
    raise CommError(err.response, err)
wandb.errors.CommError: <Response [400]>

2022-06-16 13:58:00 ERROR 400 response executing GraphQL.
2022-06-16 13:58:00 ERROR {"errors":[{"message":"name required for project query","path":["project"]}],"data":{"project":null}}
2022-06-16 13:58:00 ERROR Traceback (most recent call last):
  File "/Users/petr/Documents/fun_stuff/auto_song_labeller/nerAL/lib/python3.8/site-packages/wandb/apis/normalize.py", line 22, in wrapper
    return func(*args, **kwargs)
  File "/Users/petr/Documents/fun_stuff/auto_song_labeller/nerAL/lib/python3.8/site-packages/wandb/sdk/internal/internal_api.py", line 571, in sweep
    response = self.gql(
  File "/Users/petr/Documents/fun_stuff/auto_song_labeller/nerAL/lib/python3.8/site-packages/wandb/sdk/lib/retry.py", line 102, in __call__
    result = self._call_fn(*args, **kwargs)
  File "/Users/petr/Documents/fun_stuff/auto_song_labeller/nerAL/lib/python3.8/site-packages/wandb/sdk/internal/internal_api.py", line 140, in execute
    return self.client.execute(*args, **kwargs)
  File "/Users/petr/Documents/fun_stuff/auto_song_labeller/nerAL/lib/python3.8/site-packages/wandb/vendor/gql-0.2.0/wandb_gql/client.py", line 52, in execute
    result = self._get_result(document, *args, **kwargs)
  File "/Users/petr/Documents/fun_stuff/auto_song_labeller/nerAL/lib/python3.8/site-packages/wandb/vendor/gql-0.2.0/wandb_gql/client.py", line 60, in _get_result
    return self.transport.execute(document, *args, **kwargs)
  File "/Users/petr/Documents/fun_stuff/auto_song_labeller/nerAL/lib/python3.8/site-packages/wandb/vendor/gql-0.2.0/wandb_gql/transport/requests.py", line 39, in execute
    request.raise_for_status()
  File "/Users/petr/Documents/fun_stuff/auto_song_labeller/nerAL/lib/python3.8/site-packages/requests/models.py", line 1022, in raise_for_status
    raise HTTPError(http_error_msg, response=self)
requests.exceptions.HTTPError: 400 Client Error: Bad Request for url: https://api.wandb.ai/graphql

During handling of the above exception, another exception occurred:

Traceback (most recent call last):
  File "/Users/petr/Documents/fun_stuff/auto_song_labeller/nerAL/lib/python3.8/site-packages/wandb/cli/cli.py", line 96, in wrapper
    return func(*args, **kwargs)
  File "/Users/petr/Documents/fun_stuff/auto_song_labeller/nerAL/lib/python3.8/site-packages/wandb/cli/cli.py", line 1210, in agent
    wandb_agent.agent(sweep_id, entity=entity, project=project, count=count)
  File "/Users/petr/Documents/fun_stuff/auto_song_labeller/nerAL/lib/python3.8/site-packages/wandb/wandb_agent.py", line 606, in agent
    return run_agent(
  File "/Users/petr/Documents/fun_stuff/auto_song_labeller/nerAL/lib/python3.8/site-packages/wandb/wandb_agent.py", line 548, in run_agent
    agent.run()
  File "/Users/petr/Documents/fun_stuff/auto_song_labeller/nerAL/lib/python3.8/site-packages/wandb/wandb_agent.py", line 181, in run
    sweep_obj = self._api.sweep(self._sweep_id, "{}")
  File "/Users/petr/Documents/fun_stuff/auto_song_labeller/nerAL/lib/python3.8/site-packages/wandb/apis/internal.py", line 99, in sweep
    return self.api.sweep(*args, **kwargs)
  File "/Users/petr/Documents/fun_stuff/auto_song_labeller/nerAL/lib/python3.8/site-packages/wandb/apis/normalize.py", line 24, in wrapper
    raise CommError(err.response, err)
wandb.errors.CommError: <Response [400]>

